Workbook
Name AD: 'Phương án'!$A$3:$B$6
Name dm_quocgia: 'DM Quốc tịch'!$B$2:$B$242
Name dmtinh: '[1]Danh mục'!$H$3:$H$36
Name DS_tinh: OFFSET(Huyen!$A$2, MATCH(DuLieu!$BX$1, Huyen!$A$2:$A$3322, 0)-1, 2, COUNTIF(Huyen!$A$2:$A$3322,DuLieu!$BX$1), 1)
Name huong_BHYT: 'DM Mức hưởng BHYT'!$A$2:$A$6
Name huongbhyt: 'DM Mức hưởng BHYT'!$A$2:$A$6
Name loaipa: 'Loại PA'!$B$2:$B$5
Name Loc_trung_huyen: Huyen!$D$2:$D$3322
Name Loc_trung_xa: Xa!$E$2:$E$10039
Name ma__tinh: '[1]Danh mục'!$G:$G
Name Ma_Benh: '[1]Mã bệnh'!$A$2:$A$673
Name Ma_huyen: Huyen!$B$2:$B$3322
Name ma_quocgia: 'DM Quốc tịch'!$A:$A
Name Ma_Tinh: '[1]Danh mục'!$G$3:$G$65
Name ma_tinh: Tinhcu!$A$2:$A$66
Name ma_tinh: Tinh!$A$2:$A$37
Name Ma_xa: Xa!$C$2:$C$10039
Name mabenhvien: KCB!$B$2:$B$12456
Name madantoc: 'Dân tộc'!$A$2:$A$57
Name magioitinh: GioiTinh!$A:$A
Name magt: GioiTinh!$A$2:$A$3
Name mahuong: 'DM Mức hưởng BHYT'!$A$2:$A$6
Name mahuyen: Huyen!$B$2:$B$707
Name mahuyen_xa: Xa!$B:$B
Name maloaipa: 'Loại PA'!$A$2:$A$5
Name mamoiquanhe: 'Mối quan hệ'!$A$2:$A$24
Name manganhang: '[1]Ngân hàng'!$B$2:$B$6027
Name Manhomhuong: '[1]Danh mục'!$J$3:$J$30
Name MaNhomHuongC2_ThaiSan: '[1]Danh mục'!$O$3:$O$41
Name maphuongan: 'Phương án'!$A$3:$A$7
Name maquocgia: 'DM Quốc tịch'!$A$2:$A$242
Name maquoctich: 'DM Quốc tịch'!$A$2:$A$242
Name matinh: '[1]Ngân hàng'!$A:$A
Name matinh: Tinhcu!$A$2:$A$66
Name matinh: Tinh!$A$2:$A$37
Name matinh_huyen: Huyen!$A$2:$A$3322
Name matinh_xa: Xa!$A:$A
Name matinhbenhvien: KCB!$A:$A
Name matinhcu: Tinhcu!$A$2:$A$64
Name matinhnganhang: '[1]Ngân hàng'!$A:$A
Name Matinhnganhangcu: '[1]Tỉnh cũ'!$A$3:$A$66
Name moiquanhe: 'Mối quan hệ'!$B$2:$B$24
Name muchuong: 'DM Mức hưởng BHYT'!$1:$1048576
Name muchuongbhxh: 'DM Mức hưởng BHYT'!$B$2:$B$6
Name NhomHuong_DuongSuc: '[1]Danh mục'!$R$3:$R$12
Name NhomHuong_OmDau: '[1]Danh mục'!$B$3:$B$5
Name NhomHuong_ThaiSan: '[1]Danh mục'!$K$3:$K$13
Name Phuongan: 'Phương án'!$A$3:$A$6
Name phuongan1: 'Phương án'!$A$3:$A$7
Name Ten_huyen: Huyen!$C$2:$C$3322
Name Ten_tinh: Tinhcu!$B$2:$B$66
Name Ten_tinh: Tinh!$B$2:$B$37
Name ten_xa: Xa!$D$2:$D$10039
Name tenbenhvien: KCB!$C:$C
Name tenbenhvien_matinhbenhvien: KCB!$D$2:$D$12456
Name tendantoc: 'Dân tộc'!$B$2:$B$57
Name tengioitinh: GioiTinh!$B:$B
Name tennganhang_matinhnganhang: '[1]Ngân hàng'!$D$2:$D$6027
Name TennhomhuongC1: '[1]Danh mục'!$K$3:$K$13
Name TenNhomHuongC2_ThaiSan: '[1]Danh mục'!$P$3:$P$41

Sheet DuLieu
A1: DANH SÁCH NGƯỜI THAM GIA BHXH TỰ NGUYỆN (Mẫu D05-TS TK1) * Ghi chú: Các cột màu xanh là dữ liệu tự động, không được sửa. Cột có dấu (*), đơn vị bắt buộc kê khai | AH1: Phần nhập dành cho tờ khai TK01 (Chỉ dành cho người chưa có mã số BHXH) | BP1: Đối với trẻ em dưới 6 tuổi | BR1: Nếu đã có mã số BHXH thì không cần phải nhập các cột từ đây về sau
A2: STT | B2: Họ và tên (*) | C2: Mã số BHXH | D2: Số CCCD/ĐDCN/Hộ chiếu | E2: Loại phương án (*) | F2: Mã loại PA | G2: Phương án (*) | H2: Mã PA | I2: Phương thức đóng (*) | J2: Số tháng đóng (*) | K2: Tháng/năm bắt đầu đóng(*) (MM/yyyy) | L2: Mức tiền đóng (*) | M2: Hệ số (*) | N2: Tỷ lệ đóng BHXH tự nguyện (%) | O2: NSNN hỗ trợ (*) | Q2: Ngân sách địa phương hỗ trợ | S2: Hỗ trợ khác | U2: Tổng tiền phải đóng (*) | V2: Mức tiền tự đóng (*) | W2: Số biên lai | X2: Ngày biên lai (*) | Y2: Mã số nhân viên thu | Z2: Địa chỉ đang sinh sống | AE2: Ghi chú | AF2: Đã có sổ | AG2: Xuất TK01 (Có - TRUE, Không - FALSE ) | AH2: Loại ngày sinh | AI2: Ngày sinh | AJ2: Giới tính | AK2: Tên Quốc tịch (*) | AL2: Quốc tịch | AM2: Tên Dân tộc (*) | AN2: Dân tộc | AO2: Điện thoại liên hệ | AP2: CMND/CCCD | AQ2: Email liên hệ | AR2: Thông tin đăng ký khai sinh | AW2: Thông tin địa chỉ nhận hồ sơ | BB2: Nơi Đăng ký Khám chữa bệnh ban đầu | BF2: Đăng ký nhận sổ và thẻ | BG2: Địa chỉ nhận Sổ, thẻ | BL2: Mức tiền đóng | BM2: Phương thức đóng | BN2: Nội dung thay đổi | BO2: Hồ sơ kèm theo | BP2: Họ tên người giám hộ | BQ2: Mã số hộ gia đình | BR2: Thông tin hộ khẩu
O3: Tỷ lệ (*) (%) | P3: Số tiền NSNN hỗ trợ (*) | Q3: Tỷ lệ (%) | R3: Số tiền hỗ trợ | S3: Tỷ lệ (%) | T3: Số tiền hỗ trợ | Z3: Tỉnh/Thành phố | AA3: Mã Tỉnh/TP | AB3: Xã/Phường | AC3: Mã Xã/Phường | AD3: Địa chỉ cụ thể | AR3: Tỉnh / Thành phố (*) | AS3: Mã Tỉnh | AT3: Phường/ Xã (*) | AU3: Mã xã | AV3: Địa chỉ khai sinh | AW3: Tỉnh / Thành phố (*) | AX3: Mã Tỉnh | AY3: Phường/ Xã (*) | AZ3: Mã xã | BA3: Địa chỉ nhận hồ sơ (*) | BB3: Tỉnh nơi KCB | BC3: Mã tỉnh | BD3: Nơi đăng ký KCB ban đầu | BE3: Mã BV | BG3: Tỉnh / Thành phố | BH3: Mã Tỉnh | BI3: Phường/ Xã | BJ3: Mã Xã | BK3: Địa chỉ nhận Sổ thẻ | BR3: Họ Tên chủ hộ (*) | BS3: CMND/CCCD | BT3: Điện thoại | BU3: Loại giấy tờ | BV3: Số giấy tờ | BW3: Tỉnh / Thành phố | BX3: Mã Tỉnh | BY3: Phường/ Xã | BZ3: Mã xã | CA3: Tổ/ Thôn/ Xóm | CB3: Địa chỉ hộ khẩu | CC3: Tỉnh / Thành phố thường trú (*) | CD3: Mã Tỉnh | CE3: Phường/ Xã thường trú (*) | CF3: Mã xã | CG3: Địa chỉ thường trú | CH3: Mã số hộ gia đình
A4: STT | B4: HoTen | C4: MaSoBhxh | D4: Cmnd | E4: TenLoaiHoSo | F4: LoaiHoSo | G4: PhuongAn | H4: PhuongAnId | I4: PhuongThucDong | J4: SoThang | K4: TuThang | L4: MucTien | M4: HeSo | N4: TyLe | O4: TyLeNsnn | P4: TienHoTro | Q4: TyLeNSDP | R4: TienNSDP | S4: TyLeHoTroKhac | T4: TienHoTroKhac | U4: TongTien | V4: TienTuDong | W4: SoBienLai | X4: NgayBienLai | Y4: MaNhanVienThu | Z4: Tinh_DangSS | AA4: MaTinh_DangSS | AB4: Xa_DangSS | AC4: MaXa_DangSS | AD4: DiaChi_DangSS | AE4: GhiChu | AF4: DaCoSo | AG4: XuatTk01 | AH4: ChiCoNamSinh | AI4: NgaySinh | AJ4: GioiTinh | AK4: QuocTich | AL4: QuocTichId | AM4: DanToc | AN4: DanTocId | AO4: DienThoaiLienHe | AP4: Cmnd1 | AQ4: Email | AR4: KhaiSinhTinh | AS4: KhaiSinhTinhId | AT4: KhaiSinhXa | AU4: KhaiSinhXaId | AV4: DiaChiKhaiSinh | AW4: NoiNhanTinh | AX4: NoiNhanTinhId | AY4: NoiNhanXa | AZ4: NoiNhanXaId | BA4: NoiNhanDiaChiChiTiet | BB4: BenhVienTinh | BC4: BenhVienTinhId | BD4: BenhVien | BE4: BenhVienId | BF4: DangKyNhanSoThe | BG4: TinhNhanBanGiay | BH4: TinhNhanBanGiayId | BI4: XaNhanBanGiay | BJ4: XaNhanBanGiayId | BK4: DiaChiNhanBanGiay | BL4: MucDongTk01 | BM4: PhuongThucTk1 | BN4: NoiDungThayDoi | BO4: HoSoKemTheo | BP4: HoTenNguoiGiamHo | BQ4: MaHoGiaDinh | BR4: HoTenChuHo | BS4: ChuHoSoCCCD | BT4: DienThoaiChuHo | BU4: LoaiGiayToId | BV4: SoGiayTo | BW4: ChuHoTinh | BX4: ChuHoTinhId | BY4: ChuHoXa | BZ4: ChuHoXaId | CA4: ChuHoThonId | CB4: DiaChiHoKhau | CC4: ChuHoThuongTruTinh | CD4: ChuHoThuongTruTinhId | CE4: ChuHoThuongTruXa | CF4: ChuHoThuongTruXaId | CG4: DiaChiThuongTruChuHo | CH4: MaSoHoGiaDinh | CI4: KEY_D03TS_TK01595_122019
F6: =IF(ISBLANK(E6),"",INDEX('Loại PA'!$A$1:$B$5,MATCH(E6,'Loại PA'!$B$1:$B$5,0),1)) | H6: =IF(ISBLANK(G6),"",INDEX('Phương án'!$A$3:$A$11,MATCH(G6,'Phương án'!$B$3:$B$11,0))) | AA6: =IF(ISBLANK(Z6),"",INDEX(ma_tinh,MATCH(Z6,Ten_tinh,0))) | AC6: =IF(ISBLANK(AB6),"",INDEX(Ma_huyen,MATCH(CONCATENATE(AA6,"-",AB6),Loc_trung_huyen,0))) | AL6: =IF(ISBLANK(AK6),"",INDEX(maquocgia,MATCH(AK6,dm_quocgia,0))) | AN6: =IF(ISBLANK(AM6),"",INDEX(madantoc,MATCH(AM6,tendantoc,0))) | AS6: =IF(ISBLANK(AR6),"",INDEX(ma_tinh,MATCH(AR6,Ten_tinh,0))) | AU6: =IF(ISBLANK(AT6),"",INDEX(Ma_huyen,MATCH(CONCATENATE(AS6,"-",AT6),Loc_trung_huyen,0))) | AX6: =IF(ISBLANK(AW6),"",INDEX(ma_tinh,MATCH(AW6,Ten_tinh,0))) | AZ6: =IF(ISBLANK(AY6),"",INDEX(Ma_huyen,MATCH(CONCATENATE(AX6,"-",AY6),Loc_trung_huyen,0))) | BC6: =IF(ISBLANK(BB6),"",INDEX(Tinh!$A$2:$A$35,MATCH(BB6,Tinh!$B$2:$B$35,0))) | BE6: =IF(ISBLANK(BD6),"",INDEX(mabenhvien,MATCH(BD6&BC6,tenbenhvien_matinhbenhvien,0))) | BH6: =IF(ISBLANK(BG6),"",INDEX(ma_tinh,MATCH(BG6,Ten_tinh,0))) | BJ6: =IF(ISBLANK(BI6),"",INDEX(Ma_huyen,MATCH(CONCATENATE(BH6,"-",BI6),Loc_trung_huyen,0))) | BX6: =IF(ISBLANK(BW6),"",INDEX(matinh,MATCH(BW6,Ten_tinh,0))) | BZ6: =IF(ISBLANK(BY6),"",INDEX(Ma_huyen,MATCH(CONCATENATE(BX6,"-",BY6),Loc_trung_huyen,0))) | CD6: =IF(ISBLANK(CC6),"",INDEX(matinh,MATCH(CC6,Ten_tinh,0))) | CF6: =IF(ISBLANK(CE6),"",INDEX(Ma_huyen,MATCH(CONCATENATE(CD6,"-",CE6),Loc_trung_huyen,0)))
F7: =IF(ISBLANK(E7),"",INDEX('Loại PA'!$A$1:$B$5,MATCH(E7,'Loại PA'!$B$1:$B$5,0),1)) | H7: =IF(ISBLANK(G7),"",INDEX('Phương án'!$A$3:$A$11,MATCH(G7,'Phương án'!$B$3:$B$11,0))) | AA7: =IF(ISBLANK(Z7),"",INDEX(ma_tinh,MATCH(Z7,Ten_tinh,0))) | AC7: =IF(ISBLANK(AB7),"",INDEX(Ma_huyen,MATCH(CONCATENATE(AA7,"-",AB7),Loc_trung_huyen,0))) | AL7: =IF(ISBLANK(AK7),"",INDEX(maquocgia,MATCH(AK7,dm_quocgia,0))) | AN7: =IF(ISBLANK(AM7),"",INDEX(madantoc,MATCH(AM7,tendantoc,0))) | AS7: =IF(ISBLANK(AR7),"",INDEX(ma_tinh,MATCH(AR7,Ten_tinh,0))) | AU7: =IF(ISBLANK(AT7),"",INDEX(Ma_huyen,MATCH(CONCATENATE(AS7,"-",AT7),Loc_trung_huyen,0))) | AX7: =IF(ISBLANK(AW7),"",INDEX(ma_tinh,MATCH(AW7,Ten_tinh,0))) | AZ7: =IF(ISBLANK(AY7),"",INDEX(Ma_huyen,MATCH(CONCATENATE(AX7,"-",AY7),Loc_trung_huyen,0))) | BC7: =IF(ISBLANK(BB7),"",INDEX(Tinh!$A$2:$A$35,MATCH(BB7,Tinh!$B$2:$B$35,0))) | BE7: =IF(ISBLANK(BD7),"",INDEX(mabenhvien,MATCH(BD7&BC7,tenbenhvien_matinhbenhvien,0))) | BH7: =IF(ISBLANK(BG7),"",INDEX(ma_tinh,MATCH(BG7,Ten_tinh,0))) | BJ7: =IF(ISBLANK(BI7),"",INDEX(Ma_huyen,MATCH(CONCATENATE(BH7,"-",BI7),Loc_trung_huyen,0))) | BX7: =IF(ISBLANK(BW7),"",INDEX(matinh,MATCH(BW7,Ten_tinh,0))) | BZ7: =IF(ISBLANK(BY7),"",INDEX(Ma_huyen,MATCH(CONCATENATE(BX7,"-",BY7),Loc_trung_huyen,0))) | CD7: =IF(ISBLANK(CC7),"",INDEX(matinh,MATCH(CC7,Ten_tinh,0))) | CF7: =IF(ISBLANK(CE7),"",INDEX(Ma_huyen,MATCH(CONCATENATE(CD7,"-",CE7),Loc_trung_huyen,0)))
F8: =IF(ISBLANK(E8),"",INDEX('Loại PA'!$A$1:$B$5,MATCH(E8,'Loại PA'!$B$1:$B$5,0),1)) | H8: =IF(ISBLANK(G8),"",INDEX('Phương án'!$A$3:$A$11,MATCH(G8,'Phương án'!$B$3:$B$11,0))) | AA8: =IF(ISBLANK(Z8),"",INDEX(ma_tinh,MATCH(Z8,Ten_tinh,0))) | AC8: =IF(ISBLANK(AB8),"",INDEX(Ma_huyen,MATCH(CONCATENATE(AA8,"-",AB8),Loc_trung_huyen,0))) | AL8: =IF(ISBLANK(AK8),"",INDEX(maquocgia,MATCH(AK8,dm_quocgia,0))) | AN8: =IF(ISBLANK(AM8),"",INDEX(madantoc,MATCH(AM8,tendantoc,0))) | AS8: =IF(ISBLANK(AR8),"",INDEX(ma_tinh,MATCH(AR8,Ten_tinh,0))) | AU8: =IF(ISBLANK(AT8),"",INDEX(Ma_huyen,MATCH(CONCATENATE(AS8,"-",AT8),Loc_trung_huyen,0))) | AX8: =IF(ISBLANK(AW8),"",INDEX(ma_tinh,MATCH(AW8,Ten_tinh,0))) | AZ8: =IF(ISBLANK(AY8),"",INDEX(Ma_huyen,MATCH(CONCATENATE(AX8,"-",AY8),Loc_trung_huyen,0))) | BC8: =IF(ISBLANK(BB8),"",INDEX(Tinh!$A$2:$A$35,MATCH(BB8,Tinh!$B$2:$B$35,0))) | BE8: =IF(ISBLANK(BD8),"",INDEX(mabenhvien,MATCH(BD8&BC8,tenbenhvien_matinhbenhvien,0))) | BH8: =IF(ISBLANK(BG8),"",INDEX(ma_tinh,MATCH(BG8,Ten_tinh,0))) | BJ8: =IF(ISBLANK(BI8),"",INDEX(Ma_huyen,MATCH(CONCATENATE(BH8,"-",BI8),Loc_trung_huyen,0))) | BX8: =IF(ISBLANK(BW8),"",INDEX(matinh,MATCH(BW8,Ten_tinh,0))) | BZ8: =IF(ISBLANK(BY8),"",INDEX(Ma_huyen,MATCH(CONCATENATE(BX8,"-",BY8),Loc_trung_huyen,0))) | CD8: =IF(ISBLANK(CC8),"",INDEX(matinh,MATCH(CC8,Ten_tinh,0))) | CF8: =IF(ISBLANK(CE8),"",INDEX(Ma_huyen,MATCH(CONCATENATE(CD8,"-",CE8),Loc_trung_huyen,0)))
F9: =IF(ISBLANK(E9),"",INDEX('Loại PA'!$A$1:$B$5,MATCH(E9,'Loại PA'!$B$1:$B$5,0),1)) | H9: =IF(ISBLANK(G9),"",INDEX('Phương án'!$A$3:$A$11,MATCH(G9,'Phương án'!$B$3:$B$11,0))) | AA9: =IF(ISBLANK(Z9),"",INDEX(ma_tinh,MATCH(Z9,Ten_tinh,0))) | AC9: =IF(ISBLANK(AB9),"",INDEX(Ma_huyen,MATCH(CONCATENATE(AA9,"-",AB9),Loc_trung_huyen,0))) | AL9: =IF(ISBLANK(AK9),"",INDEX(maquocgia,MATCH(AK9,dm_quocgia,0))) | AN9: =IF(ISBLANK(AM9),"",INDEX(madantoc,MATCH(AM9,tendantoc,0))) | AS9: =IF(ISBLANK(AR9),"",INDEX(ma_tinh,MATCH(AR9,Ten_tinh,0))) | AU9: =IF(ISBLANK(AT9),"",INDEX(Ma_huyen,MATCH(CONCATENATE(AS9,"-",AT9),Loc_trung_huyen,0))) | AX9: =IF(ISBLANK(AW9),"",INDEX(ma_tinh,MATCH(AW9,Ten_tinh,0))) | AZ9: =IF(ISBLANK(AY9),"",INDEX(Ma_huyen,MATCH(CONCATENATE(AX9,"-",AY9),Loc_trung_huyen,0))) | BC9: =IF(ISBLANK(BB9),"",INDEX(Tinh!$A$2:$A$35,MATCH(BB9,Tinh!$B$2:$B$35,0))) | BE9: =IF(ISBLANK(BD9),"",INDEX(mabenhvien,MATCH(BD9&BC9,tenbenhvien_matinhbenhvien,0))) | BH9: =IF(ISBLANK(BG9),"",INDEX(ma_tinh,MATCH(BG9,Ten_tinh,0))) | BJ9: =IF(ISBLANK(BI9),"",INDEX(Ma_huyen,MATCH(CONCATENATE(BH9,"-",BI9),Loc_trung_huyen,0))) | BX9: =IF(ISBLANK(BW9),"",INDEX(matinh,MATCH(BW9,Ten_tinh,0))) | BZ9: =IF(ISBLANK(BY9),"",INDEX(Ma_huyen,MATCH(CONCATENATE(BX9,"-",BY9),Loc_trung_huyen,0))) | CD9: =IF(ISBLANK(CC9),"",INDEX(matinh,MATCH(CC9,Ten_tinh,0))) | CF9: =IF(ISBLANK(CE9),"",INDEX(Ma_huyen,MATCH(CONCATENATE(CD9,"-",CE9),Loc_trung_huyen,0)))
F10: =IF(ISBLANK(E10),"",INDEX('Loại PA'!$A$1:$B$5,MATCH(E10,'Loại PA'!$B$1:$B$5,0),1)) | H10: =IF(ISBLANK(G10),"",INDEX('Phương án'!$A$3:$A$11,MATCH(G10,'Phương án'!$B$3:$B$11,0))) | AA10: =IF(ISBLANK(Z10),"",INDEX(ma_tinh,MATCH(Z10,Ten_tinh,0))) | AC10: =IF(ISBLANK(AB10),"",INDEX(Ma_huyen,MATCH(CONCATENATE(AA10,"-",AB10),Loc_trung_huyen,0))) | AL10: =IF(ISBLANK(AK10),"",INDEX(maquocgia,MATCH(AK10,dm_quocgia,0))) | AN10: =IF(ISBLANK(AM10),"",INDEX(madantoc,MATCH(AM10,tendantoc,0))) | AS10: =IF(ISBLANK(AR10),"",INDEX(ma_tinh,MATCH(AR10,Ten_tinh,0))) | AU10: =IF(ISBLANK(AT10),"",INDEX(Ma_huyen,MATCH(CONCATENATE(AS10,"-",AT10),Loc_trung_huyen,0))) | AX10: =IF(ISBLANK(AW10),"",INDEX(ma_tinh,MATCH(AW10,Ten_tinh,0))) | AZ10: =IF(ISBLANK(AY10),"",INDEX(Ma_huyen,MATCH(CONCATENATE(AX10,"-",AY10),Loc_trung_huyen,0))) | BC10: =IF(ISBLANK(BB10),"",INDEX(Tinh!$A$2:$A$35,MATCH(BB10,Tinh!$B$2:$B$35,0))) | BE10: =IF(ISBLANK(BD10),"",INDEX(mabenhvien,MATCH(BD10&BC10,tenbenhvien_matinhbenhvien,0))) | BH10: =IF(ISBLANK(BG10),"",INDEX(ma_tinh,MATCH(BG10,Ten_tinh,0))) | BJ10: =IF(ISBLANK(BI10),"",INDEX(Ma_huyen,MATCH(CONCATENATE(BH10,"-",BI10),Loc_trung_huyen,0))) | BX10: =IF(ISBLANK(BW10),"",INDEX(matinh,MATCH(BW10,Ten_tinh,0))) | BZ10: =IF(ISBLANK(BY10),"",INDEX(Ma_huyen,MATCH(CONCATENATE(BX10,"-",BY10),Loc_trung_huyen,0))) | CD10: =IF(ISBLANK(CC10),"",INDEX(matinh,MATCH(CC10,Ten_tinh,0))) | CF10: =IF(ISBLANK(CE10),"",INDEX(Ma_huyen,MATCH(CONCATENATE(CD10,"-",CE10),Loc_trung_huyen,0)))
F11: =IF(ISBLANK(E11),"",INDEX('Loại PA'!$A$1:$B$5,MATCH(E11,'Loại PA'!$B$1:$B$5,0),1)) | H11: =IF(ISBLANK(G11),"",INDEX('Phương án'!$A$3:$A$11,MATCH(G11,'Phương án'!$B$3:$B$11,0))) | AA11: =IF(ISBLANK(Z11),"",INDEX(ma_tinh,MATCH(Z11,Ten_tinh,0))) | AC11: =IF(ISBLANK(AB11),"",INDEX(Ma_huyen,MATCH(CONCATENATE(AA11,"-",AB11),Loc_trung_huyen,0))) | AL11: =IF(ISBLANK(AK11),"",INDEX(maquocgia,MATCH(AK11,dm_quocgia,0))) | AN11: =IF(ISBLANK(AM11),"",INDEX(madantoc,MATCH(AM11,tendantoc,0))) | AS11: =IF(ISBLANK(AR11),"",INDEX(ma_tinh,MATCH(AR11,Ten_tinh,0))) | AU11: =IF(ISBLANK(AT11),"",INDEX(Ma_huyen,MATCH(CONCATENATE(AS11,"-",AT11),Loc_trung_huyen,0))) | AX11: =IF(ISBLANK(AW11),"",INDEX(ma_tinh,MATCH(AW11,Ten_tinh,0))) | AZ11: =IF(ISBLANK(AY11),"",INDEX(Ma_huyen,MATCH(CONCATENATE(AX11,"-",AY11),Loc_trung_huyen,0))) | BC11: =IF(ISBLANK(BB11),"",INDEX(Tinh!$A$2:$A$35,MATCH(BB11,Tinh!$B$2:$B$35,0))) | BE11: =IF(ISBLANK(BD11),"",INDEX(mabenhvien,MATCH(BD11&BC11,tenbenhvien_matinhbenhvien,0))) | BH11: =IF(ISBLANK(BG11),"",INDEX(ma_tinh,MATCH(BG11,Ten_tinh,0))) | BJ11: =IF(ISBLANK(BI11),"",INDEX(Ma_huyen,MATCH(CONCATENATE(BH11,"-",BI11),Loc_trung_huyen,0))) | BX11: =IF(ISBLANK(BW11),"",INDEX(matinh,MATCH(BW11,Ten_tinh,0))) | BZ11: =IF(ISBLANK(BY11),"",INDEX(Ma_huyen,MATCH(CONCATENATE(BX11,"-",BY11),Loc_trung_huyen,0))) | CD11: =IF(ISBLANK(CC11),"",INDEX(matinh,MATCH(CC11,Ten_tinh,0))) | CF11: =IF(ISBLANK(CE11),"",INDEX(Ma_huyen,MATCH(CONCATENATE(CD11,"-",CE11),Loc_trung_huyen,0)))
F12: =IF(ISBLANK(E12),"",INDEX('Loại PA'!$A$1:$B$5,MATCH(E12,'Loại PA'!$B$1:$B$5,0),1)) | H12: =IF(ISBLANK(G12),"",INDEX('Phương án'!$A$3:$A$11,MATCH(G12,'Phương án'!$B$3:$B$11,0))) | AA12: =IF(ISBLANK(Z12),"",INDEX(ma_tinh,MATCH(Z12,Ten_tinh,0))) | AC12: =IF(ISBLANK(AB12),"",INDEX(Ma_huyen,MATCH(CONCATENATE(AA12,"-",AB12),Loc_trung_huyen,0))) | AL12: =IF(ISBLANK(AK12),"",INDEX(maquocgia,MATCH(AK12,dm_quocgia,0))) | AN12: =IF(ISBLANK(AM12),"",INDEX(madantoc,MATCH(AM12,tendantoc,0))) | AS12: =IF(ISBLANK(AR12),"",INDEX(ma_tinh,MATCH(AR12,Ten_tinh,0))) | AU12: =IF(ISBLANK(AT12),"",INDEX(Ma_huyen,MATCH(CONCATENATE(AS12,"-",AT12),Loc_trung_huyen,0))) | AX12: =IF(ISBLANK(AW12),"",INDEX(ma_tinh,MATCH(AW12,Ten_tinh,0))) | AZ12: =IF(ISBLANK(AY12),"",INDEX(Ma_huyen,MATCH(CONCATENATE(AX12,"-",AY12),Loc_trung_huyen,0))) | BC12: =IF(ISBLANK(BB12),"",INDEX(Tinh!$A$2:$A$35,MATCH(BB12,Tinh!$B$2:$B$35,0))) | BE12: =IF(ISBLANK(BD12),"",INDEX(mabenhvien,MATCH(BD12&BC12,tenbenhvien_matinhbenhvien,0))) | BH12: =IF(ISBLANK(BG12),"",INDEX(ma_tinh,MATCH(BG12,Ten_tinh,0))) | BJ12: =IF(ISBLANK(BI12),"",INDEX(Ma_huyen,MATCH(CONCATENATE(BH12,"-",BI12),Loc_trung_huyen,0))) | BX12: =IF(ISBLANK(BW12),"",INDEX(matinh,MATCH(BW12,Ten_tinh,0))) | BZ12: =IF(ISBLANK(BY12),"",INDEX(Ma_huyen,MATCH(CONCATENATE(BX12,"-",BY12),Loc_trung_huyen,0))) | CD12: =IF(ISBLANK(CC12),"",INDEX(matinh,MATCH(CC12,Ten_tinh,0))) | CF12: =IF(ISBLANK(CE12),"",INDEX(Ma_huyen,MATCH(CONCATENATE(CD12,"-",CE12),Loc_trung_huyen,0)))
F13: =IF(ISBLANK(E13),"",INDEX('Loại PA'!$A$1:$B$5,MATCH(E13,'Loại PA'!$B$1:$B$5,0),1)) | H13: =IF(ISBLANK(G13),"",INDEX('Phương án'!$A$3:$A$11,MATCH(G13,'Phương án'!$B$3:$B$11,0))) | AA13: =IF(ISBLANK(Z13),"",INDEX(ma_tinh,MATCH(Z13,Ten_tinh,0))) | AC13: =IF(ISBLANK(AB13),"",INDEX(Ma_huyen,MATCH(CONCATENATE(AA13,"-",AB13),Loc_trung_huyen,0))) | AL13: =IF(ISBLANK(AK13),"",INDEX(maquocgia,MATCH(AK13,dm_quocgia,0))) | AN13: =IF(ISBLANK(AM13),"",INDEX(madantoc,MATCH(AM13,tendantoc,0))) | AS13: =IF(ISBLANK(AR13),"",INDEX(ma_tinh,MATCH(AR13,Ten_tinh,0))) | AU13: =IF(ISBLANK(AT13),"",INDEX(Ma_huyen,MATCH(CONCATENATE(AS13,"-",AT13),Loc_trung_huyen,0))) | AX13: =IF(ISBLANK(AW13),"",INDEX(ma_tinh,MATCH(AW13,Ten_tinh,0))) | AZ13: =IF(ISBLANK(AY13),"",INDEX(Ma_huyen,MATCH(CONCATENATE(AX13,"-",AY13),Loc_trung_huyen,0))) | BC13: =IF(ISBLANK(BB13),"",INDEX(Tinh!$A$2:$A$35,MATCH(BB13,Tinh!$B$2:$B$35,0))) | BE13: =IF(ISBLANK(BD13),"",INDEX(mabenhvien,MATCH(BD13&BC13,tenbenhvien_matinhbenhvien,0))) | BH13: =IF(ISBLANK(BG13),"",INDEX(ma_tinh,MATCH(BG13,Ten_tinh,0))) | BJ13: =IF(ISBLANK(BI13),"",INDEX(Ma_huyen,MATCH(CONCATENATE(BH13,"-",BI13),Loc_trung_huyen,0))) | BX13: =IF(ISBLANK(BW13),"",INDEX(matinh,MATCH(BW13,Ten_tinh,0))) | BZ13: =IF(ISBLANK(BY13),"",INDEX(Ma_huyen,MATCH(CONCATENATE(BX13,"-",BY13),Loc_trung_huyen,0))) | CD13: =IF(ISBLANK(CC13),"",INDEX(matinh,MATCH(CC13,Ten_tinh,0))) | CF13: =IF(ISBLANK(CE13),"",INDEX(Ma_huyen,MATCH(CONCATENATE(CD13,"-",CE13),Loc_trung_huyen,0)))
F14: =IF(ISBLANK(E14),"",INDEX('Loại PA'!$A$1:$B$5,MATCH(E14,'Loại PA'!$B$1:$B$5,0),1)) | H14: =IF(ISBLANK(G14),"",INDEX('Phương án'!$A$3:$A$11,MATCH(G14,'Phương án'!$B$3:$B$11,0))) | AA14: =IF(ISBLANK(Z14),"",INDEX(ma_tinh,MATCH(Z14,Ten_tinh,0))) | AC14: =IF(ISBLANK(AB14),"",INDEX(Ma_huyen,MATCH(CONCATENATE(AA14,"-",AB14),Loc_trung_huyen,0))) | AL14: =IF(ISBLANK(AK14),"",INDEX(maquocgia,MATCH(AK14,dm_quocgia,0))) | AN14: =IF(ISBLANK(AM14),"",INDEX(madantoc,MATCH(AM14,tendantoc,0))) | AS14: =IF(ISBLANK(AR14),"",INDEX(ma_tinh,MATCH(AR14,Ten_tinh,0))) | AU14: =IF(ISBLANK(AT14),"",INDEX(Ma_huyen,MATCH(CONCATENATE(AS14,"-",AT14),Loc_trung_huyen,0))) | AX14: =IF(ISBLANK(AW14),"",INDEX(ma_tinh,MATCH(AW14,Ten_tinh,0))) | AZ14: =IF(ISBLANK(AY14),"",INDEX(Ma_huyen,MATCH(CONCATENATE(AX14,"-",AY14),Loc_trung_huyen,0))) | BC14: =IF(ISBLANK(BB14),"",INDEX(Tinh!$A$2:$A$35,MATCH(BB14,Tinh!$B$2:$B$35,0))) | BE14: =IF(ISBLANK(BD14),"",INDEX(mabenhvien,MATCH(BD14&BC14,tenbenhvien_matinhbenhvien,0))) | BH14: =IF(ISBLANK(BG14),"",INDEX(ma_tinh,MATCH(BG14,Ten_tinh,0))) | BJ14: =IF(ISBLANK(BI14),"",INDEX(Ma_huyen,MATCH(CONCATENATE(BH14,"-",BI14),Loc_trung_huyen,0))) | BX14: =IF(ISBLANK(BW14),"",INDEX(matinh,MATCH(BW14,Ten_tinh,0))) | BZ14: =IF(ISBLANK(BY14),"",INDEX(Ma_huyen,MATCH(CONCATENATE(BX14,"-",BY14),Loc_trung_huyen,0))) | CD14: =IF(ISBLANK(CC14),"",INDEX(matinh,MATCH(CC14,Ten_tinh,0))) | CF14: =IF(ISBLANK(CE14),"",INDEX(Ma_huyen,MATCH(CONCATENATE(CD14,"-",CE14),Loc_trung_huyen,0)))
F15: =IF(ISBLANK(E15),"",INDEX('Loại PA'!$A$1:$B$5,MATCH(E15,'Loại PA'!$B$1:$B$5,0),1)) | H15: =IF(ISBLANK(G15),"",INDEX('Phương án'!$A$3:$A$11,MATCH(G15,'Phương án'!$B$3:$B$11,0))) | AA15: =IF(ISBLANK(Z15),"",INDEX(ma_tinh,MATCH(Z15,Ten_tinh,0))) | AC15: =IF(ISBLANK(AB15),"",INDEX(Ma_huyen,MATCH(CONCATENATE(AA15,"-",AB15),Loc_trung_huyen,0))) | AL15: =IF(ISBLANK(AK15),"",INDEX(maquocgia,MATCH(AK15,dm_quocgia,0))) | AN15: =IF(ISBLANK(AM15),"",INDEX(madantoc,MATCH(AM15,tendantoc,0))) | AS15: =IF(ISBLANK(AR15),"",INDEX(ma_tinh,MATCH(AR15,Ten_tinh,0))) | AU15: =IF(ISBLANK(AT15),"",INDEX(Ma_huyen,MATCH(CONCATENATE(AS15,"-",AT15),Loc_trung_huyen,0))) | AX15: =IF(ISBLANK(AW15),"",INDEX(ma_tinh,MATCH(AW15,Ten_tinh,0))) | AZ15: =IF(ISBLANK(AY15),"",INDEX(Ma_huyen,MATCH(CONCATENATE(AX15,"-",AY15),Loc_trung_huyen,0))) | BC15: =IF(ISBLANK(BB15),"",INDEX(Tinh!$A$2:$A$35,MATCH(BB15,Tinh!$B$2:$B$35,0))) | BE15: =IF(ISBLANK(BD15),"",INDEX(mabenhvien,MATCH(BD15&BC15,tenbenhvien_matinhbenhvien,0))) | BH15: =IF(ISBLANK(BG15),"",INDEX(ma_tinh,MATCH(BG15,Ten_tinh,0))) | BJ15: =IF(ISBLANK(BI15),"",INDEX(Ma_huyen,MATCH(CONCATENATE(BH15,"-",BI15),Loc_trung_huyen,0))) | BX15: =IF(ISBLANK(BW15),"",INDEX(matinh,MATCH(BW15,Ten_tinh,0))) | BZ15: =IF(ISBLANK(BY15),"",INDEX(Ma_huyen,MATCH(CONCATENATE(BX15,"-",BY15),Loc_trung_huyen,0))) | CD15: =IF(ISBLANK(CC15),"",INDEX(matinh,MATCH(CC15,Ten_tinh,0))) | CF15: =IF(ISBLANK(CE15),"",INDEX(Ma_huyen,MATCH(CONCATENATE(CD15,"-",CE15),Loc_trung_huyen,0)))
F16: =IF(ISBLANK(E16),"",INDEX('Loại PA'!$A$1:$B$5,MATCH(E16,'Loại PA'!$B$1:$B$5,0),1)) | H16: =IF(ISBLANK(G16),"",INDEX('Phương án'!$A$3:$A$11,MATCH(G16,'Phương án'!$B$3:$B$11,0))) | AA16: =IF(ISBLANK(Z16),"",INDEX(ma_tinh,MATCH(Z16,Ten_tinh,0))) | AC16: =IF(ISBLANK(AB16),"",INDEX(Ma_huyen,MATCH(CONCATENATE(AA16,"-",AB16),Loc_trung_huyen,0))) | AL16: =IF(ISBLANK(AK16),"",INDEX(maquocgia,MATCH(AK16,dm_quocgia,0))) | AN16: =IF(ISBLANK(AM16),"",INDEX(madantoc,MATCH(AM16,tendantoc,0))) | AS16: =IF(ISBLANK(AR16),"",INDEX(ma_tinh,MATCH(AR16,Ten_tinh,0))) | AU16: =IF(ISBLANK(AT16),"",INDEX(Ma_huyen,MATCH(CONCATENATE(AS16,"-",AT16),Loc_trung_huyen,0))) | AX16: =IF(ISBLANK(AW16),"",INDEX(ma_tinh,MATCH(AW16,Ten_tinh,0))) | AZ16: =IF(ISBLANK(AY16),"",INDEX(Ma_huyen,MATCH(CONCATENATE(AX16,"-",AY16),Loc_trung_huyen,0))) | BC16: =IF(ISBLANK(BB16),"",INDEX(Tinh!$A$2:$A$35,MATCH(BB16,Tinh!$B$2:$B$35,0))) | BE16: =IF(ISBLANK(BD16),"",INDEX(mabenhvien,MATCH(BD16&BC16,tenbenhvien_matinhbenhvien,0))) | BH16: =IF(ISBLANK(BG16),"",INDEX(ma_tinh,MATCH(BG16,Ten_tinh,0))) | BJ16: =IF(ISBLANK(BI16),"",INDEX(Ma_huyen,MATCH(CONCATENATE(BH16,"-",BI16),Loc_trung_huyen,0))) | BX16: =IF(ISBLANK(BW16),"",INDEX(matinh,MATCH(BW16,Ten_tinh,0))) | BZ16: =IF(ISBLANK(BY16),"",INDEX(Ma_huyen,MATCH(CONCATENATE(BX16,"-",BY16),Loc_trung_huyen,0))) | CD16: =IF(ISBLANK(CC16),"",INDEX(matinh,MATCH(CC16,Ten_tinh,0))) | CF16: =IF(ISBLANK(CE16),"",INDEX(Ma_huyen,MATCH(CONCATENATE(CD16,"-",CE16),Loc_trung_huyen,0)))
F17: =IF(ISBLANK(E17),"",INDEX('Loại PA'!$A$1:$B$5,MATCH(E17,'Loại PA'!$B$1:$B$5,0),1)) | H17: =IF(ISBLANK(G17),"",INDEX('Phương án'!$A$3:$A$11,MATCH(G17,'Phương án'!$B$3:$B$11,0))) | AA17: =IF(ISBLANK(Z17),"",INDEX(ma_tinh,MATCH(Z17,Ten_tinh,0))) | AC17: =IF(ISBLANK(AB17),"",INDEX(Ma_huyen,MATCH(CONCATENATE(AA17,"-",AB17),Loc_trung_huyen,0))) | AL17: =IF(ISBLANK(AK17),"",INDEX(maquocgia,MATCH(AK17,dm_quocgia,0))) | AN17: =IF(ISBLANK(AM17),"",INDEX(madantoc,MATCH(AM17,tendantoc,0))) | AS17: =IF(ISBLANK(AR17),"",INDEX(ma_tinh,MATCH(AR17,Ten_tinh,0))) | AU17: =IF(ISBLANK(AT17),"",INDEX(Ma_huyen,MATCH(CONCATENATE(AS17,"-",AT17),Loc_trung_huyen,0))) | AX17: =IF(ISBLANK(AW17),"",INDEX(ma_tinh,MATCH(AW17,Ten_tinh,0))) | AZ17: =IF(ISBLANK(AY17),"",INDEX(Ma_huyen,MATCH(CONCATENATE(AX17,"-",AY17),Loc_trung_huyen,0))) | BC17: =IF(ISBLANK(BB17),"",INDEX(Tinh!$A$2:$A$35,MATCH(BB17,Tinh!$B$2:$B$35,0))) | BE17: =IF(ISBLANK(BD17),"",INDEX(mabenhvien,MATCH(BD17&BC17,tenbenhvien_matinhbenhvien,0))) | BH17: =IF(ISBLANK(BG17),"",INDEX(ma_tinh,MATCH(BG17,Ten_tinh,0))) | BJ17: =IF(ISBLANK(BI17),"",INDEX(Ma_huyen,MATCH(CONCATENATE(BH17,"-",BI17),Loc_trung_huyen,0))) | BX17: =IF(ISBLANK(BW17),"",INDEX(matinh,MATCH(BW17,Ten_tinh,0))) | BZ17: =IF(ISBLANK(BY17),"",INDEX(Ma_huyen,MATCH(CONCATENATE(BX17,"-",BY17),Loc_trung_huyen,0))) | CD17: =IF(ISBLANK(CC17),"",INDEX(matinh,MATCH(CC17,Ten_tinh,0))) | CF17: =IF(ISBLANK(CE17),"",INDEX(Ma_huyen,MATCH(CONCATENATE(CD17,"-",CE17),Loc_trung_huyen,0)))
... F406: =IF(ISBLANK(E406),"",INDEX('Loại PA'!$A$1:$B$5,MATCH(E406,'Loại PA'!$B$1:$B$5,0),1)) | H406: =IF(ISBLANK(G406),"",INDEX('Phương án'!$A$3:$A$11,MATCH(G406,'Phương án'!$B$3:$B$11,0))) | AA406: =IF(ISBLANK(Z406),"",INDEX(ma_tinh,MATCH(Z406,Ten_tinh,0))) | AC406: =IF(ISBLANK(AB406),"",INDEX(Ma_huyen,MATCH(CONCATENATE(AA406,"-",AB406),Loc_trung_huyen,0))) | AL406: =IF(ISBLANK(AK406),"",INDEX(maquocgia,MATCH(AK406,dm_quocgia,0))) | AN406: =IF(ISBLANK(AM406),"",INDEX(madantoc,MATCH(AM406,tendantoc,0))) | AS406: =IF(ISBLANK(AR406),"",INDEX(ma_tinh,MATCH(AR406,Ten_tinh,0))) | AU406: =IF(ISBLANK(AT406),"",INDEX(Ma_huyen,MATCH(CONCATENATE(AS406,"-",AT406),Loc_trung_huyen,0))) | AX406: =IF(ISBLANK(AW406),"",INDEX(ma_tinh,MATCH(AW406,Ten_tinh,0))) | AZ406: =IF(ISBLANK(AY406),"",INDEX(Ma_huyen,MATCH(CONCATENATE(AX406,"-",AY406),Loc_trung_huyen,0))) | BC406: =IF(ISBLANK(BB406),"",INDEX(Tinh!$A$2:$A$35,MATCH(BB406,Tinh!$B$2:$B$35,0))) | BE406: =IF(ISBLANK(BD406),"",INDEX(mabenhvien,MATCH(BD406&BC406,tenbenhvien_matinhbenhvien,0))) | BH406: =IF(ISBLANK(BG406),"",INDEX(ma_tinh,MATCH(BG406,Ten_tinh,0))) | BJ406: =IF(ISBLANK(BI406),"",INDEX(Ma_huyen,MATCH(CONCATENATE(BH406,"-",BI406),Loc_trung_huyen,0))) | BX406: =IF(ISBLANK(BW406),"",INDEX(matinh,MATCH(BW406,Ten_tinh,0))) | BZ406: =IF(ISBLANK(BY406),"",INDEX(Ma_huyen,MATCH(CONCATENATE(BX406,"-",BY406),Loc_trung_huyen,0))) | CD406: =IF(ISBLANK(CC406),"",INDEX(matinh,MATCH(CC406,Ten_tinh,0))) | CF406: =IF(ISBLANK(CE406),"",INDEX(Ma_huyen,MATCH(CONCATENATE(CD406,"-",CE406),Loc_trung_huyen,0)))
F407: =IF(ISBLANK(E407),"",INDEX('Loại PA'!$A$1:$B$5,MATCH(E407,'Loại PA'!$B$1:$B$5,0),1)) | H407: =IF(ISBLANK(G407),"",INDEX('Phương án'!$A$3:$A$11,MATCH(G407,'Phương án'!$B$3:$B$11,0))) | AA407: =IF(ISBLANK(Z407),"",INDEX(ma_tinh,MATCH(Z407,Ten_tinh,0))) | AC407: =IF(ISBLANK(AB407),"",INDEX(Ma_huyen,MATCH(CONCATENATE(AA407,"-",AB407),Loc_trung_huyen,0))) | BC407: =IF(ISBLANK(BB407),"",INDEX(Tinh!$A$2:$A$35,MATCH(BB407,Tinh!$B$2:$B$35,0))) | BE407: =IF(ISBLANK(BD407),"",INDEX(mabenhvien,MATCH(BD407&BC407,tenbenhvien_matinhbenhvien,0)))
F408: =IF(ISBLANK(E408),"",INDEX('Loại PA'!$A$1:$B$5,MATCH(E408,'Loại PA'!$B$1:$B$5,0),1)) | H408: =IF(ISBLANK(G408),"",INDEX('Phương án'!$A$3:$A$11,MATCH(G408,'Phương án'!$B$3:$B$11,0))) | AA408: =IF(ISBLANK(Z408),"",INDEX(ma_tinh,MATCH(Z408,Ten_tinh,0))) | AC408: =IF(ISBLANK(AB408),"",INDEX(Ma_huyen,MATCH(CONCATENATE(AA408,"-",AB408),Loc_trung_huyen,0))) | BC408: =IF(ISBLANK(BB408),"",INDEX(Tinh!$A$2:$A$35,MATCH(BB408,Tinh!$B$2:$B$35,0))) | BE408: =IF(ISBLANK(BD408),"",INDEX(mabenhvien,MATCH(BD408&BC408,tenbenhvien_matinhbenhvien,0)))
F409: =IF(ISBLANK(E409),"",INDEX('Loại PA'!$A$1:$B$5,MATCH(E409,'Loại PA'!$B$1:$B$5,0),1)) | H409: =IF(ISBLANK(G409),"",INDEX('Phương án'!$A$3:$A$11,MATCH(G409,'Phương án'!$B$3:$B$11,0))) | AA409: =IF(ISBLANK(Z409),"",INDEX(ma_tinh,MATCH(Z409,Ten_tinh,0))) | AC409: =IF(ISBLANK(AB409),"",INDEX(Ma_huyen,MATCH(CONCATENATE(AA409,"-",AB409),Loc_trung_huyen,0))) | BC409: =IF(ISBLANK(BB409),"",INDEX(Tinh!$A$2:$A$35,MATCH(BB409,Tinh!$B$2:$B$35,0))) | BE409: =IF(ISBLANK(BD409),"",INDEX(mabenhvien,MATCH(BD409&BC409,tenbenhvien_matinhbenhvien,0)))
F410: =IF(ISBLANK(E410),"",INDEX('Loại PA'!$A$1:$B$5,MATCH(E410,'Loại PA'!$B$1:$B$5,0),1)) | H410: =IF(ISBLANK(G410),"",INDEX('Phương án'!$A$3:$A$11,MATCH(G410,'Phương án'!$B$3:$B$11,0))) | AA410: =IF(ISBLANK(Z410),"",INDEX(ma_tinh,MATCH(Z410,Ten_tinh,0))) | AC410: =IF(ISBLANK(AB410),"",INDEX(Ma_huyen,MATCH(CONCATENATE(AA410,"-",AB410),Loc_trung_huyen,0))) | BC410: =IF(ISBLANK(BB410),"",INDEX(Tinh!$A$2:$A$35,MATCH(BB410,Tinh!$B$2:$B$35,0))) | BE410: =IF(ISBLANK(BD410),"",INDEX(mabenhvien,MATCH(BD410&BC410,tenbenhvien_matinhbenhvien,0)))
F411: =IF(ISBLANK(E411),"",INDEX('Loại PA'!$A$1:$B$5,MATCH(E411,'Loại PA'!$B$1:$B$5,0),1)) | H411: =IF(ISBLANK(G411),"",INDEX('Phương án'!$A$3:$A$11,MATCH(G411,'Phương án'!$B$3:$B$11,0))) | AA411: =IF(ISBLANK(Z411),"",INDEX(ma_tinh,MATCH(Z411,Ten_tinh,0))) | AC411: =IF(ISBLANK(AB411),"",INDEX(Ma_huyen,MATCH(CONCATENATE(AA411,"-",AB411),Loc_trung_huyen,0))) | BC411: =IF(ISBLANK(BB411),"",INDEX(Tinh!$A$2:$A$35,MATCH(BB411,Tinh!$B$2:$B$35,0))) | BE411: =IF(ISBLANK(BD411),"",INDEX(mabenhvien,MATCH(BD411&BC411,tenbenhvien_matinhbenhvien,0)))
F412: =IF(ISBLANK(E412),"",INDEX('Loại PA'!$A$1:$B$5,MATCH(E412,'Loại PA'!$B$1:$B$5,0),1)) | H412: =IF(ISBLANK(G412),"",INDEX('Phương án'!$A$3:$A$11,MATCH(G412,'Phương án'!$B$3:$B$11,0))) | AA412: =IF(ISBLANK(Z412),"",INDEX(ma_tinh,MATCH(Z412,Ten_tinh,0))) | AC412: =IF(ISBLANK(AB412),"",INDEX(Ma_huyen,MATCH(CONCATENATE(AA412,"-",AB412),Loc_trung_huyen,0))) | BC412: =IF(ISBLANK(BB412),"",INDEX(Tinh!$A$2:$A$35,MATCH(BB412,Tinh!$B$2:$B$35,0))) | BE412: =IF(ISBLANK(BD412),"",INDEX(mabenhvien,MATCH(BD412&BC412,tenbenhvien_matinhbenhvien,0)))
F413: =IF(ISBLANK(E413),"",INDEX('Loại PA'!$A$1:$B$5,MATCH(E413,'Loại PA'!$B$1:$B$5,0),1)) | H413: =IF(ISBLANK(G413),"",INDEX('Phương án'!$A$3:$A$11,MATCH(G413,'Phương án'!$B$3:$B$11,0))) | AA413: =IF(ISBLANK(Z413),"",INDEX(ma_tinh,MATCH(Z413,Ten_tinh,0))) | AC413: =IF(ISBLANK(AB413),"",INDEX(Ma_huyen,MATCH(CONCATENATE(AA413,"-",AB413),Loc_trung_huyen,0))) | BC413: =IF(ISBLANK(BB413),"",INDEX(Tinh!$A$2:$A$35,MATCH(BB413,Tinh!$B$2:$B$35,0))) | BE413: =IF(ISBLANK(BD413),"",INDEX(mabenhvien,MATCH(BD413&BC413,tenbenhvien_matinhbenhvien,0)))
F414: =IF(ISBLANK(E414),"",INDEX('Loại PA'!$A$1:$B$5,MATCH(E414,'Loại PA'!$B$1:$B$5,0),1)) | H414: =IF(ISBLANK(G414),"",INDEX('Phương án'!$A$3:$A$11,MATCH(G414,'Phương án'!$B$3:$B$11,0))) | AA414: =IF(ISBLANK(Z414),"",INDEX(ma_tinh,MATCH(Z414,Ten_tinh,0))) | AC414: =IF(ISBLANK(AB414),"",INDEX(Ma_huyen,MATCH(CONCATENATE(AA414,"-",AB414),Loc_trung_huyen,0))) | BC414: =IF(ISBLANK(BB414),"",INDEX(Tinh!$A$2:$A$35,MATCH(BB414,Tinh!$B$2:$B$35,0))) | BE414: =IF(ISBLANK(BD414),"",INDEX(mabenhvien,MATCH(BD414&BC414,tenbenhvien_matinhbenhvien,0)))
F415: =IF(ISBLANK(E415),"",INDEX('Loại PA'!$A$1:$B$5,MATCH(E415,'Loại PA'!$B$1:$B$5,0),1)) | H415: =IF(ISBLANK(G415),"",INDEX('Phương án'!$A$3:$A$11,MATCH(G415,'Phương án'!$B$3:$B$11,0))) | AA415: =IF(ISBLANK(Z415),"",INDEX(ma_tinh,MATCH(Z415,Ten_tinh,0))) | AC415: =IF(ISBLANK(AB415),"",INDEX(Ma_huyen,MATCH(CONCATENATE(AA415,"-",AB415),Loc_trung_huyen,0))) | BC415: =IF(ISBLANK(BB415),"",INDEX(Tinh!$A$2:$A$35,MATCH(BB415,Tinh!$B$2:$B$35,0))) | BE415: =IF(ISBLANK(BD415),"",INDEX(mabenhvien,MATCH(BD415&BC415,tenbenhvien_matinhbenhvien,0)))
F416: =IF(ISBLANK(E416),"",INDEX('Loại PA'!$A$1:$B$5,MATCH(E416,'Loại PA'!$B$1:$B$5,0),1)) | H416: =IF(ISBLANK(G416),"",INDEX('Phương án'!$A$3:$A$11,MATCH(G416,'Phương án'!$B$3:$B$11,0))) | AA416: =IF(ISBLANK(Z416),"",INDEX(ma_tinh,MATCH(Z416,Ten_tinh,0))) | AC416: =IF(ISBLANK(AB416),"",INDEX(Ma_huyen,MATCH(CONCATENATE(AA416,"-",AB416),Loc_trung_huyen,0))) | BC416: =IF(ISBLANK(BB416),"",INDEX(Tinh!$A$2:$A$35,MATCH(BB416,Tinh!$B$2:$B$35,0))) | BE416: =IF(ISBLANK(BD416),"",INDEX(mabenhvien,MATCH(BD416&BC416,tenbenhvien_matinhbenhvien,0)))
F417: =IF(ISBLANK(E417),"",INDEX('Loại PA'!$A$1:$B$5,MATCH(E417,'Loại PA'!$B$1:$B$5,0),1)) | H417: =IF(ISBLANK(G417),"",INDEX('Phương án'!$A$3:$A$11,MATCH(G417,'Phương án'!$B$3:$B$11,0))) | AA417: =IF(ISBLANK(Z417),"",INDEX(ma_tinh,MATCH(Z417,Ten_tinh,0))) | AC417: =IF(ISBLANK(AB417),"",INDEX(Ma_huyen,MATCH(CONCATENATE(AA417,"-",AB417),Loc_trung_huyen,0))) | BC417: =IF(ISBLANK(BB417),"",INDEX(Tinh!$A$2:$A$35,MATCH(BB417,Tinh!$B$2:$B$35,0))) | BE417: =IF(ISBLANK(BD417),"",INDEX(mabenhvien,MATCH(BD417&BC417,tenbenhvien_matinhbenhvien,0)))
F418: =IF(ISBLANK(E418),"",INDEX('Loại PA'!$A$1:$B$5,MATCH(E418,'Loại PA'!$B$1:$B$5,0),1)) | H418: =IF(ISBLANK(G418),"",INDEX('Phương án'!$A$3:$A$11,MATCH(G418,'Phương án'!$B$3:$B$11,0))) | AA418: =IF(ISBLANK(Z418),"",INDEX(ma_tinh,MATCH(Z418,Ten_tinh,0))) | AC418: =IF(ISBLANK(AB418),"",INDEX(Ma_huyen,MATCH(CONCATENATE(AA418,"-",AB418),Loc_trung_huyen,0))) | BC418: =IF(ISBLANK(BB418),"",INDEX(Tinh!$A$2:$A$35,MATCH(BB418,Tinh!$B$2:$B$35,0))) | BE418: =IF(ISBLANK(BD418),"",INDEX(mabenhvien,MATCH(BD418&BC418,tenbenhvien_matinhbenhvien,0)))
... F1086: =IF(ISBLANK(E1086),"",INDEX('Loại PA'!$A$1:$B$5,MATCH(E1086,'Loại PA'!$B$1:$B$5,0),1)) | H1086: =IF(ISBLANK(G1086),"",INDEX('Phương án'!$A$3:$A$11,MATCH(G1086,'Phương án'!$B$3:$B$11,0))) | AA1086: =IF(ISBLANK(Z1086),"",INDEX(ma_tinh,MATCH(Z1086,Ten_tinh,0))) | AC1086: =IF(ISBLANK(AB1086),"",INDEX(Ma_huyen,MATCH(CONCATENATE(AA1086,"-",AB1086),Loc_trung_huyen,0))) | BC1086: =IF(ISBLANK(BB1086),"",INDEX(Tinh!$A$2:$A$35,MATCH(BB1086,Tinh!$B$2:$B$35,0))) | BE1086: =IF(ISBLANK(BD1086),"",INDEX(mabenhvien,MATCH(BD1086&BC1086,tenbenhvien_matinhbenhvien,0)))
BC1087: =IF(ISBLANK(BB1087),"",INDEX(Tinh!$A$2:$A$35,MATCH(BB1087,Tinh!$B$2:$B$35,0)))
BC1088: =IF(ISBLANK(BB1088),"",INDEX(Tinh!$A$2:$A$35,MATCH(BB1088,Tinh!$B$2:$B$35,0)))
BC1089: =IF(ISBLANK(BB1089),"",INDEX(Tinh!$A$2:$A$35,MATCH(BB1089,Tinh!$B$2:$B$35,0)))
BC1090: =IF(ISBLANK(BB1090),"",INDEX(Tinh!$A$2:$A$35,MATCH(BB1090,Tinh!$B$2:$B$35,0)))
BC1091: =IF(ISBLANK(BB1091),"",INDEX(Tinh!$A$2:$A$35,MATCH(BB1091,Tinh!$B$2:$B$35,0)))
BC1092: =IF(ISBLANK(BB1092),"",INDEX(Tinh!$A$2:$A$35,MATCH(BB1092,Tinh!$B$2:$B$35,0)))
BC1093: =IF(ISBLANK(BB1093),"",INDEX(Tinh!$A$2:$A$35,MATCH(BB1093,Tinh!$B$2:$B$35,0)))
BC1094: =IF(ISBLANK(BB1094),"",INDEX(Tinh!$A$2:$A$35,MATCH(BB1094,Tinh!$B$2:$B$35,0)))
BC1095: =IF(ISBLANK(BB1095),"",INDEX(Tinh!$A$2:$A$35,MATCH(BB1095,Tinh!$B$2:$B$35,0)))
BC1096: =IF(ISBLANK(BB1096),"",INDEX(Tinh!$A$2:$A$35,MATCH(BB1096,Tinh!$B$2:$B$35,0)))
...

Sheet PL TV HGĐ
A1: PHỤ LỤC THÀNH VIÊN HỘ GIA ĐÌNH
A2: * Ghi chú: Các cột màu xanh là dữ liệu tự động, không được sửa. Cột có dấu (*), đơn vị bắt buộc kê khai
A3: STT trên D05-TS (nhập STT trên Dulieu) | B3: Danh sách thành viên: Cần kê khai đầy đủ thành viên trong gia đình
B4: Họ và tên thành viên (*) | C4: Mã số BHXH | D4: Loại ngày sinh | E4: Ngày sinh (*) | F4: Giới tính (*) | G4: Tên Quốc tịch (*) | H4: Quốc tịch | I4: Tên Dân tộc (*) | J4: Dân tộc | K4: Số CCCD/ĐDCN/HC | L4: Tỉnh / Thành phố Khai sinh | M4: Mã tỉnh | N4: Phường/ Xã Khai sinh | O4: Mã xã | P4: Địa chỉ khai sinh | Q4: Mối quan hệ thành viên với chủ hộ | R4: Mã MQH | S4: Ghi chú
A5: STT_TV | B5: HoTen_TV | C5: MaSoBhxh_TV | D5: ChiCoNamSinh_TV | E5: NgaySinh_TV | F5: GioiTinh_TV | G5: QuocTich | H5: QuocTich_TV | I5: DanToc | J5: DanToc_TV | K5: Cmnd_TV | L5: KhaiSinhTinh | M5: KhaiSinhTinhId_TV | N5: KhaiSinhXa | O5: KhaiSinhXaId_TV | P5: DiaChiKhaiSinh_TV | Q5: MoiQuanHe | R5: MoiQuanHe_TV | S5: GhiChu_TV
H7: =IF(ISBLANK(G7),"",INDEX(maquocgia,MATCH(G7,dm_quocgia,0))) | J7: =IF(ISBLANK(I7),"",INDEX(madantoc,MATCH(I7,tendantoc,0))) | M7: =IF(ISBLANK(L7),"",INDEX(ma_tinh,MATCH(L7,Ten_tinh,0),1)) | O7: =IF(ISBLANK(N7),"",INDEX(Ma_huyen,MATCH(CONCATENATE(M7,"-",N7),Loc_trung_huyen,0))) | R7: =IF(ISBLANK(Q7),"",INDEX(mamoiquanhe,MATCH(Q7,moiquanhe,0)))
H8: =IF(ISBLANK(G8),"",INDEX(maquocgia,MATCH(G8,dm_quocgia,0))) | J8: =IF(ISBLANK(I8),"",INDEX(madantoc,MATCH(I8,tendantoc,0))) | M8: =IF(ISBLANK(L8),"",INDEX(ma_tinh,MATCH(L8,Ten_tinh,0),1)) | O8: =IF(ISBLANK(N8),"",INDEX(Ma_huyen,MATCH(CONCATENATE(M8,"-",N8),Loc_trung_huyen,0))) | R8: =IF(ISBLANK(Q8),"",INDEX(mamoiquanhe,MATCH(Q8,moiquanhe,0)))
H9: =IF(ISBLANK(G9),"",INDEX(maquocgia,MATCH(G9,dm_quocgia,0))) | J9: =IF(ISBLANK(I9),"",INDEX(madantoc,MATCH(I9,tendantoc,0))) | M9: =IF(ISBLANK(L9),"",INDEX(ma_tinh,MATCH(L9,Ten_tinh,0),1)) | O9: =IF(ISBLANK(N9),"",INDEX(Ma_huyen,MATCH(CONCATENATE(M9,"-",N9),Loc_trung_huyen,0))) | R9: =IF(ISBLANK(Q9),"",INDEX(mamoiquanhe,MATCH(Q9,moiquanhe,0)))
H10: =IF(ISBLANK(G10),"",INDEX(maquocgia,MATCH(G10,dm_quocgia,0))) | J10: =IF(ISBLANK(I10),"",INDEX(madantoc,MATCH(I10,tendantoc,0))) | M10: =IF(ISBLANK(L10),"",INDEX(ma_tinh,MATCH(L10,Ten_tinh,0),1)) | O10: =IF(ISBLANK(N10),"",INDEX(Ma_huyen,MATCH(CONCATENATE(M10,"-",N10),Loc_trung_huyen,0))) | R10: =IF(ISBLANK(Q10),"",INDEX(mamoiquanhe,MATCH(Q10,moiquanhe,0)))
H11: =IF(ISBLANK(G11),"",INDEX(maquocgia,MATCH(G11,dm_quocgia,0))) | J11: =IF(ISBLANK(I11),"",INDEX(madantoc,MATCH(I11,tendantoc,0))) | M11: =IF(ISBLANK(L11),"",INDEX(ma_tinh,MATCH(L11,Ten_tinh,0),1)) | O11: =IF(ISBLANK(N11),"",INDEX(Ma_huyen,MATCH(CONCATENATE(M11,"-",N11),Loc_trung_huyen,0))) | R11: =IF(ISBLANK(Q11),"",INDEX(mamoiquanhe,MATCH(Q11,moiquanhe,0)))
H12: =IF(ISBLANK(G12),"",INDEX(maquocgia,MATCH(G12,dm_quocgia,0))) | J12: =IF(ISBLANK(I12),"",INDEX(madantoc,MATCH(I12,tendantoc,0))) | M12: =IF(ISBLANK(L12),"",INDEX(ma_tinh,MATCH(L12,Ten_tinh,0),1)) | O12: =IF(ISBLANK(N12),"",INDEX(Ma_huyen,MATCH(CONCATENATE(M12,"-",N12),Loc_trung_huyen,0))) | R12: =IF(ISBLANK(Q12),"",INDEX(mamoiquanhe,MATCH(Q12,moiquanhe,0)))
H13: =IF(ISBLANK(G13),"",INDEX(maquocgia,MATCH(G13,dm_quocgia,0))) | J13: =IF(ISBLANK(I13),"",INDEX(madantoc,MATCH(I13,tendantoc,0))) | M13: =IF(ISBLANK(L13),"",INDEX(ma_tinh,MATCH(L13,Ten_tinh,0),1)) | O13: =IF(ISBLANK(N13),"",INDEX(Ma_huyen,MATCH(CONCATENATE(M13,"-",N13),Loc_trung_huyen,0))) | R13: =IF(ISBLANK(Q13),"",INDEX(mamoiquanhe,MATCH(Q13,moiquanhe,0)))
H14: =IF(ISBLANK(G14),"",INDEX(maquocgia,MATCH(G14,dm_quocgia,0))) | J14: =IF(ISBLANK(I14),"",INDEX(madantoc,MATCH(I14,tendantoc,0))) | M14: =IF(ISBLANK(L14),"",INDEX(ma_tinh,MATCH(L14,Ten_tinh,0),1)) | O14: =IF(ISBLANK(N14),"",INDEX(Ma_huyen,MATCH(CONCATENATE(M14,"-",N14),Loc_trung_huyen,0))) | R14: =IF(ISBLANK(Q14),"",INDEX(mamoiquanhe,MATCH(Q14,moiquanhe,0)))
H15: =IF(ISBLANK(G15),"",INDEX(maquocgia,MATCH(G15,dm_quocgia,0))) | J15: =IF(ISBLANK(I15),"",INDEX(madantoc,MATCH(I15,tendantoc,0))) | M15: =IF(ISBLANK(L15),"",INDEX(ma_tinh,MATCH(L15,Ten_tinh,0),1)) | O15: =IF(ISBLANK(N15),"",INDEX(Ma_huyen,MATCH(CONCATENATE(M15,"-",N15),Loc_trung_huyen,0))) | R15: =IF(ISBLANK(Q15),"",INDEX(mamoiquanhe,MATCH(Q15,moiquanhe,0)))
H16: =IF(ISBLANK(G16),"",INDEX(maquocgia,MATCH(G16,dm_quocgia,0))) | J16: =IF(ISBLANK(I16),"",INDEX(madantoc,MATCH(I16,tendantoc,0))) | M16: =IF(ISBLANK(L16),"",INDEX(ma_tinh,MATCH(L16,Ten_tinh,0),1)) | O16: =IF(ISBLANK(N16),"",INDEX(Ma_huyen,MATCH(CONCATENATE(M16,"-",N16),Loc_trung_huyen,0))) | R16: =IF(ISBLANK(Q16),"",INDEX(mamoiquanhe,MATCH(Q16,moiquanhe,0)))
H17: =IF(ISBLANK(G17),"",INDEX(maquocgia,MATCH(G17,dm_quocgia,0))) | J17: =IF(ISBLANK(I17),"",INDEX(madantoc,MATCH(I17,tendantoc,0))) | M17: =IF(ISBLANK(L17),"",INDEX(ma_tinh,MATCH(L17,Ten_tinh,0),1)) | O17: =IF(ISBLANK(N17),"",INDEX(Ma_huyen,MATCH(CONCATENATE(M17,"-",N17),Loc_trung_huyen,0))) | R17: =IF(ISBLANK(Q17),"",INDEX(mamoiquanhe,MATCH(Q17,moiquanhe,0)))
H18: =IF(ISBLANK(G18),"",INDEX(maquocgia,MATCH(G18,dm_quocgia,0))) | J18: =IF(ISBLANK(I18),"",INDEX(madantoc,MATCH(I18,tendantoc,0))) | M18: =IF(ISBLANK(L18),"",INDEX(ma_tinh,MATCH(L18,Ten_tinh,0),1)) | O18: =IF(ISBLANK(N18),"",INDEX(Ma_huyen,MATCH(CONCATENATE(M18,"-",N18),Loc_trung_huyen,0))) | R18: =IF(ISBLANK(Q18),"",INDEX(mamoiquanhe,MATCH(Q18,moiquanhe,0)))
... H2996: =IF(ISBLANK(G2996),"",INDEX(maquocgia,MATCH(G2996,dm_quocgia,0))) | J2996: =IF(ISBLANK(I2996),"",INDEX(madantoc,MATCH(I2996,tendantoc,0))) | M2996: =IF(ISBLANK(L2996),"",INDEX(ma_tinh,MATCH(L2996,Ten_tinh,0),1)) | O2996: =IF(ISBLANK(N2996),"",INDEX(Ma_huyen,MATCH(CONCATENATE(M2996,"-",N2996),Loc_trung_huyen,0))) | R2996: =IF(ISBLANK(Q2996),"",INDEX(mamoiquanhe,MATCH(Q2996,moiquanhe,0)))

Sheet D01-TS
A1: BẢNG KÊ THÔNG TIN (MẪU D01-TS) Các cột có dấu (*) là thông tin bắt buộc nhập Hướng dẫn: Nhập số thứ tự tương ứng với STT người lao động bên sheet Dulieu
A3: STT (*) | B3: Họ và tên (*) | C3: Mã số BHXH | D3: Tên loại văn bản (*) | E3: Số văn bản (*) | F3: Ngày ban hành văn bản (*) | G3: Ngày văn bản có hiệu lực (*) | H3: Cơ quan ban hành văn bản (*) | I3: Trích yếu văn bản (*) | J3: Nội dung thẩm định (*)
A4: STT | B4: HoTen | C4: MaSoBHXH | D4: TenLoaiVanBan | E4: SoVanBan | F4: NgayBanHanh | G4: NgayHieuLuc | H4: CoQuanBanHanh | I4: TrichYeu | J4: NoiDungThamDinh | K4: KEY_D01TS_595_122019

Sheet TemplateKey
A1: KEY_D05TS_TK01595_V2_101225

Sheet Tylegiamtru
A1: Người tham gia thứ | B1: Tỷ lệ giảm trừ (%)
A2: Thứ nhất | B2: 0
A3: Thứ hai | B3: 30
A4: Thứ ba | B4: 40
A5: Thứ tư | B5: 50
A6: Thứ năm trở đi | B6: 60

Sheet Tinh
A1: Mã | B1: Tỉnh/thành phố
A2: 01 | B2: 01 - Thành phố Hà Nội
A3: 04 | B3: 04 - Tỉnh Cao Bằng
A4: 08 | B4: 08 - Tỉnh Tuyên Quang
A5: 11 | B5: 11 - Tỉnh Điện Biên
A6: 12 | B6: 12 - Tỉnh Lai Châu
A7: 14 | B7: 14 - Tỉnh Sơn La
A8: 15 | B8: 15 - Tỉnh Lào Cai
A9: 19 | B9: 19 - Tỉnh Thái Nguyên
A10: 20 | B10: 20 - Tỉnh Lạng Sơn
A11: 22 | B11: 22 - Tỉnh Quảng Ninh
A12: 24 | B12: 24 - Tỉnh Bắc Ninh
A13: 25 | B13: 25 - Tỉnh Phú Thọ
A14: 31 | B14: 31 - Thành phố Hải Phòng
A15: 33 | B15: 33 - Tỉnh Hưng Yên
A16: 37 | B16: 37 - Tỉnh Ninh Bình
... A35: 96 | B35: 96 - Tỉnh Cà Mau

Sheet Huyen
A1: MaTinh | B1: MaHuyen | C1: TenHuyen | D1: Lọc trùng
A2: 01 | B2: 00070 | C2: Phường Hoàn Kiếm | D2: =CONCATENATE(A2,"-",C2) -> 01-Phường Hoàn Kiếm
A3: 01 | B3: 00082 | C3: Phường Cửa Nam | D3: =CONCATENATE(A3,"-",C3) -> 01-Phường Cửa Nam
A4: 01 | B4: 00004 | C4: Phường Ba Đình | D4: =CONCATENATE(A4,"-",C4) -> 01-Phường Ba Đình
A5: 01 | B5: 00008 | C5: Phường Ngọc Hà | D5: =CONCATENATE(A5,"-",C5) -> 01-Phường Ngọc Hà
A6: 01 | B6: 00025 | C6: Phường Giảng Võ | D6: =CONCATENATE(A6,"-",C6) -> 01-Phường Giảng Võ
A7: 01 | B7: 00256 | C7: Phường Hai Bà Trưng | D7: =CONCATENATE(A7,"-",C7) -> 01-Phường Hai Bà Trưng
A8: 01 | B8: 00283 | C8: Phường Vĩnh Tuy | D8: =CONCATENATE(A8,"-",C8) -> 01-Phường Vĩnh Tuy
A9: 01 | B9: 00292 | C9: Phường Bạch Mai | D9: =CONCATENATE(A9,"-",C9) -> 01-Phường Bạch Mai
A10: 01 | B10: 00235 | C10: Phường Đống Đa | D10: =CONCATENATE(A10,"-",C10) -> 01-Phường Đống Đa
A11: 01 | B11: 00229 | C11: Phường Kim Liên | D11: =CONCATENATE(A11,"-",C11) -> 01-Phường Kim Liên
A12: 01 | B12: 00226 | C12: Phường Văn Miếu - Quốc Tử Giám | D12: =CONCATENATE(A12,"-",C12) -> 01-Phường Văn Miếu - Quốc Tử Giám
A13: 01 | B13: 00199 | C13: Phường Láng | D13: =CONCATENATE(A13,"-",C13) -> 01-Phường Láng
... A307: 08 | B307: 01147 | C307: Xã Khuôn Lùng | D307: =CONCATENATE(A307,"-",C307) -> 08-Xã Khuôn Lùng
A308: 11 | B308: 03325 | C308: Xã Mường Phăng | D308: =CONCATENATE(A308,"-",C308) -> 11-Xã Mường Phăng
A309: 11 | B309: 03127 | C309: Phường Điện Biên Phủ | D309: =CONCATENATE(A309,"-",C309) -> 11-Phường Điện Biên Phủ
A310: 11 | B310: 03334 | C310: Phường Mường Thanh | D310: =CONCATENATE(A310,"-",C310) -> 11-Phường Mường Thanh
A311: 11 | B311: 03151 | C311: Phường Mường Lay | D311: =CONCATENATE(A311,"-",C311) -> 11-Phường Mường Lay
A312: 11 | B312: 03328 | C312: Xã Thanh Nưa | D312: =CONCATENATE(A312,"-",C312) -> 11-Xã Thanh Nưa
A313: 11 | B313: 03352 | C313: Xã Thanh An | D313: =CONCATENATE(A313,"-",C313) -> 11-Xã Thanh An
A314: 11 | B314: 03349 | C314: Xã Thanh Yên | D314: =CONCATENATE(A314,"-",C314) -> 11-Xã Thanh Yên
A315: 11 | B315: 03356 | C315: Xã Sam Mứn | D315: =CONCATENATE(A315,"-",C315) -> 11-Xã Sam Mứn
A316: 11 | B316: 03358 | C316: Xã Núa Ngam | D316: =CONCATENATE(A316,"-",C316) -> 11-Xã Núa Ngam
A317: 11 | B317: 03368 | C317: Xã Mường Nhà | D317: =CONCATENATE(A317,"-",C317) -> 11-Xã Mường Nhà
A318: 11 | B318: 03253 | C318: Xã Tuần Giáo | D318: =CONCATENATE(A318,"-",C318) -> 11-Xã Tuần Giáo
A319: 11 | B319: 03295 | C319: Xã Quài Tở | D319: =CONCATENATE(A319,"-",C319) -> 11-Xã Quài Tở
... A1118: 31 | B1118: 11113 | C1118: Xã Tân Kỳ | D1118: =CONCATENATE(A1118,"-",C1118) -> 31-Xã Tân Kỳ
A1119: 31 | B1119: 11086 | C1119: Xã Đại Sơn | D1119: =CONCATENATE(A1119,"-",C1119) -> 31-Xã Đại Sơn
A1120: 31 | B1120: 11131 | C1120: Xã Chí Minh | D1120: =CONCATENATE(A1120,"-",C1120) -> 31-Xã Chí Minh
A1121: 31 | B1121: 11140 | C1121: Xã Lạc Phượng | D1121: =CONCATENATE(A1121,"-",C1121) -> 31-Xã Lạc Phượng
A1122: 31 | B1122: 11146 | C1122: Xã Nguyên Giáp | D1122: =CONCATENATE(A1122,"-",C1122) -> 31-Xã Nguyên Giáp
A1123: 31 | B1123: 11203 | C1123: Xã Ninh Giang | D1123: =CONCATENATE(A1123,"-",C1123) -> 31-Xã Ninh Giang
A1124: 31 | B1124: 11164 | C1124: Xã Vĩnh Lại | D1124: =CONCATENATE(A1124,"-",C1124) -> 31-Xã Vĩnh Lại
A1125: 31 | B1125: 11224 | C1125: Xã Khúc Thừa Dụ | D1125: =CONCATENATE(A1125,"-",C1125) -> 31-Xã Khúc Thừa Dụ
A1126: 31 | B1126: 11167 | C1126: Xã Tân An | D1126: =CONCATENATE(A1126,"-",C1126) -> 31-Xã Tân An
A1127: 31 | B1127: 11218 | C1127: Xã Hồng Châu | D1127: =CONCATENATE(A1127,"-",C1127) -> 31-Xã Hồng Châu
A1128: 31 | B1128: 11239 | C1128: Xã Thanh Miện | D1128: =CONCATENATE(A1128,"-",C1128) -> 31-Xã Thanh Miện
A1129: 31 | B1129: 11254 | C1129: Xã Bắc Thanh Miện | D1129: =CONCATENATE(A1129,"-",C1129) -> 31-Xã Bắc Thanh Miện
A1130: 31 | B1130: 11257 | C1130: Xã Hải Hưng | D1130: =CONCATENATE(A1130,"-",C1130) -> 31-Xã Hải Hưng
A1131: 31 | B1131: 11242 | C1131: Xã Nguyễn Lương Bằng | D1131: =CONCATENATE(A1131,"-",C1131) -> 31-Xã Nguyễn Lương Bằng
...

Sheet Xa
A1: MaTinh | B1: MaHuyen | C1: MaXa | D1: TenXa | E1: Lọc trùng xã
A2: 01 | B2: 001 | C2: 00001 | D2: Phường Phúc Xá | E2: =CONCATENATE(B2,"-",D2) -> 001-Phường Phúc Xá
A3: 01 | B3: 001 | C3: 00004 | D3: Phường Trúc Bạch | E3: =CONCATENATE(B3,"-",D3) -> 001-Phường Trúc Bạch
A4: 01 | B4: 001 | C4: 00006 | D4: Phường Vĩnh Phúc | E4: =CONCATENATE(B4,"-",D4) -> 001-Phường Vĩnh Phúc
A5: 01 | B5: 001 | C5: 00007 | D5: Phường Cống Vị | E5: =CONCATENATE(B5,"-",D5) -> 001-Phường Cống Vị
A6: 01 | B6: 001 | C6: 00008 | D6: Phường Liễu Giai | E6: =CONCATENATE(B6,"-",D6) -> 001-Phường Liễu Giai
A7: 01 | B7: 001 | C7: 00013 | D7: Phường Quán Thánh | E7: =CONCATENATE(B7,"-",D7) -> 001-Phường Quán Thánh
A8: 01 | B8: 001 | C8: 00016 | D8: Phường Ngọc Hà | E8: =CONCATENATE(B8,"-",D8) -> 001-Phường Ngọc Hà
A9: 01 | B9: 001 | C9: 00019 | D9: Phường Điện Biên | E9: =CONCATENATE(B9,"-",D9) -> 001-Phường Điện Biên
A10: 01 | B10: 001 | C10: 00022 | D10: Phường Đội Cấn | E10: =CONCATENATE(B10,"-",D10) -> 001-Phường Đội Cấn
A11: 01 | B11: 001 | C11: 00025 | D11: Phường Ngọc Khánh | E11: =CONCATENATE(B11,"-",D11) -> 001-Phường Ngọc Khánh
A12: 01 | B12: 001 | C12: 00028 | D12: Phường Kim Mã | E12: =CONCATENATE(B12,"-",D12) -> 001-Phường Kim Mã
A13: 01 | B13: 001 | C13: 00031 | D13: Phường Giảng Võ | E13: =CONCATENATE(B13,"-",D13) -> 001-Phường Giảng Võ
... A10036: 96 | B10036: 973 | C10036: 32248 | D10036: Xã Đất Mũi | E10036: =CONCATENATE(B10036,"-",D10036) -> 973-Xã Đất Mũi

Sheet KCB
A1: MaTinh | B1: MaBenhVien | C1: TenBenhVien | D1: tenbenhvien_matinhbenhvien
A2: 01 | B2: 01001 | C2: Bệnh viện Hữu Nghị | D2: =CONCATENATE(C2,A2) -> Bệnh viện Hữu Nghị01
A3: 01 | B3: 01002 | C3: Phòng khám A thuộc BVĐK Xanh Pôn | D3: =CONCATENATE(C3,A3) -> Phòng khám A thuộc BVĐK Xanh Pôn01
A4: 01 | B4: 01003 | C4: Bệnh viện đa khoa Xanh Pôn | D4: =CONCATENATE(C4,A4) -> Bệnh viện đa khoa Xanh Pôn01
A5: 01 | B5: 01004 | C5: Bệnh viện đa khoa Đống Đa | D5: =CONCATENATE(C5,A5) -> Bệnh viện đa khoa Đống Đa01
A6: 01 | B6: 01005 | C6: Bệnh viện Hữu Nghị Việt Nam - Cu Ba | D6: =CONCATENATE(C6,A6) -> Bệnh viện Hữu Nghị Việt Nam - Cu Ba01
A7: 01 | B7: 01006 | C7: Bệnh viện Thanh Nhàn | D7: =CONCATENATE(C7,A7) -> Bệnh viện Thanh Nhàn01
A8: 01 | B8: 01007 | C8: Bệnh viện E | D8: =CONCATENATE(C8,A8) -> Bệnh viện E01
A9: 01 | B9: 01009 | C9: Bệnh viện Bưu điện | D9: =CONCATENATE(C9,A9) -> Bệnh viện Bưu điện01
A10: 01 | B10: 01010 | C10: Bệnh viện Giao thông vận tải trực thuộc CTCP Bệnh viện Giao thông vận tải | D10: =CONCATENATE(C10,A10) -> Bệnh viện Giao thông vận tải trực thuộc CTCP Bệnh viện Giao thông vận tải01
A11: 01 | B11: 01012 | C11: Phòng khám đa khoa Đông Mỹ trực thuộc Trạm Y tế xã Nam Phù | D11: =CONCATENATE(C11,A11) -> Phòng khám đa khoa Đông Mỹ trực thuộc Trạm Y tế xã Nam Phù01
A12: 01 | B12: 01013 | C12: Bệnh viện Đa khoa Nông nghiệp | D12: =CONCATENATE(C12,A12) -> Bệnh viện Đa khoa Nông nghiệp01
A13: 01 | B13: 01014 | C13: Bệnh viện trung ương Quân đội 108 | D13: =CONCATENATE(C13,A13) -> Bệnh viện trung ương Quân đội 10801
... A1227: 08 | B1227: 08708 | C1227: Điểm Trạm y tế Hồng Quang | D1227: =CONCATENATE(C1227,A1227) -> Điểm Trạm y tế Hồng Quang08
A1228: 11 | B1228: 11001 | C1228: Bệnh viện đa khoa Tỉnh | D1228: =CONCATENATE(C1228,A1228) -> Bệnh viện đa khoa Tỉnh11
A1229: 11 | B1229: 11002 | C1229: Trung tâm y tế Điện Biên Phủ | D1229: =CONCATENATE(C1229,A1229) -> Trung tâm y tế Điện Biên Phủ11
A1230: 11 | B1230: 11004 | C1230: Điểm Trạm y tế Tân Thanh | D1230: =CONCATENATE(C1230,A1230) -> Điểm Trạm y tế Tân Thanh11
A1231: 11 | B1231: 11005 | C1231: Điểm trạm y tế Thanh Bình | D1231: =CONCATENATE(C1231,A1231) -> Điểm trạm y tế Thanh Bình11
A1232: 11 | B1232: 11006 | C1232: Điểm trạm y tế Him Lam | D1232: =CONCATENATE(C1232,A1232) -> Điểm trạm y tế Him Lam11
A1233: 11 | B1233: 11007 | C1233: Điểm trạm y tế Noong Bua | D1233: =CONCATENATE(C1233,A1233) -> Điểm trạm y tế Noong Bua11
A1234: 11 | B1234: 11008 | C1234: Điểm trạm y tế Thanh Minh | D1234: =CONCATENATE(C1234,A1234) -> Điểm trạm y tế Thanh Minh11
A1235: 11 | B1235: 11009 | C1235: Điểm trạm y tế Nam Thanh | D1235: =CONCATENATE(C1235,A1235) -> Điểm trạm y tế Nam Thanh11
A1236: 11 | B1236: 11010 | C1236: Trạm Y tế Phường Điện Biên Phủ | D1236: =CONCATENATE(C1236,A1236) -> Trạm Y tế Phường Điện Biên Phủ11
A1237: 11 | B1237: 11011 | C1237: Trung tâm y tế Thanh An | D1237: =CONCATENATE(C1237,A1237) -> Trung tâm y tế Thanh An11
A1238: 11 | B1238: 11012 | C1238: Phòng khám đa khoa KV Mường Nhà | D1238: =CONCATENATE(C1238,A1238) -> Phòng khám đa khoa KV Mường Nhà11
A1239: 11 | B1239: 11015 | C1239: Điểm trạm y tế Thanh Nưa | D1239: =CONCATENATE(C1239,A1239) -> Điểm trạm y tế Thanh Nưa11
A1240: 11 | B1240: 11017 | C1240: Trạm Y tế Phường Mường Thanh | D1240: =CONCATENATE(C1240,A1240) -> Trạm Y tế Phường Mường Thanh11
... A1365: 11 | B1365: 11268 | C1365: Phòng khám đa khoa Minh Giang | D1365: =CONCATENATE(C1365,A1365) -> Phòng khám đa khoa Minh Giang11
A1366: 12 | B1366: 12001 | C1366: Bệnh viện Đa khoa Tam Đường | D1366: =CONCATENATE(C1366,A1366) -> Bệnh viện Đa khoa Tam Đường12
A1367: 12 | B1367: 12002 | C1367: Điểm Trạm y tế Số 2 xã Bình Lư | D1367: =CONCATENATE(C1367,A1367) -> Điểm Trạm y tế Số 2 xã Bình Lư12
A1368: 12 | B1368: 12003 | C1368: Trạm Y tế xã Dào San | D1368: =CONCATENATE(C1368,A1368) -> Trạm Y tế xã Dào San12
A1369: 12 | B1369: 12005 | C1369: Điểm Trạm y tế Số 1 xã Tả Lèng | D1369: =CONCATENATE(C1369,A1369) -> Điểm Trạm y tế Số 1 xã Tả Lèng12
A1370: 12 | B1370: 12007 | C1370: Trạm Y tế xã Mường Mô | D1370: =CONCATENATE(C1370,A1370) -> Trạm Y tế xã Mường Mô12
A1371: 12 | B1371: 12008 | C1371: Trạm y tế xã Pắc Ta | D1371: =CONCATENATE(C1371,A1371) -> Trạm y tế xã Pắc Ta12
A1372: 12 | B1372: 12009 | C1372: Điểm Trạm y tế Số 3 xã Tân Uyên | D1372: =CONCATENATE(C1372,A1372) -> Điểm Trạm y tế Số 3 xã Tân Uyên12
A1373: 12 | B1373: 12010 | C1373: Điểm trạm Y tế số 3 xã Mường Kim | D1373: =CONCATENATE(C1373,A1373) -> Điểm trạm Y tế số 3 xã Mường Kim12
A1374: 12 | B1374: 12011 | C1374: Trạm y tế xã Mường Kim | D1374: =CONCATENATE(C1374,A1374) -> Trạm y tế xã Mường Kim12
A1375: 12 | B1375: 12013 | C1375: Bệnh viện Đa khoa Phong Thổ | D1375: =CONCATENATE(C1375,A1375) -> Bệnh viện Đa khoa Phong Thổ12
A1376: 12 | B1376: 12014 | C1376: Bệnh viện Đa khoa Sìn Hồ | D1376: =CONCATENATE(C1376,A1376) -> Bệnh viện Đa khoa Sìn Hồ12
A1377: 12 | B1377: 12015 | C1377: Bệnh viện Đa khoa Mường Tè | D1377: =CONCATENATE(C1377,A1377) -> Bệnh viện Đa khoa Mường Tè12
...

Sheet GioiTinh
A1: Mã | B1: Giới tính
A2: 0 | B2: Nữ
A3: 1 | B3: Nam

Sheet DM Quốc tịch
A1: Mã quốc gia | B1: Tên Quốc gia/ Vùng lãnh thổ
A2: AF | B2: AFGHANISTAN
A3: AX | B3: ÅLAND ISLANDS
A4: AL | B4: ALBANIA
A5: DZ | B5: ALGERIA
A6: AS | B6: AMERICAN SAMOA
A7: AD | B7: ANDORRA
A8: AO | B8: ANGOLA
A9: AI | B9: ANGUILLA
A10: AQ | B10: ANTARCTICA
A11: AG | B11: ANTIGUA AND BARBUDA
A12: AR | B12: ARGENTINA
... A242: ZW | B242: ZIMBABWE

Sheet Dân tộc
A1: Mã Dân Tộc | B1: Tên Dân Tộc
A2: 1 | B2: Kinh
A3: 2 | B3: Tày
A4: 3 | B4: Thái
A5: 4 | B5: Hoa
A6: 5 | B6: Khơ-me
A7: 6 | B7: Mường
A8: 7 | B8: Nùng
A9: 8 | B9: Hmông
A10: 9 | B10: Dao
A11: 10 | B11: Gia-rai
A12: 11 | B12: Ngái
A13: 12 | B13: Ê-đê
A14: 13 | B14: Ba-na
A15: 14 | B15: Xơ-đăng
A16: 15 | B16: Sán Chay
A17: 16 | B17: Cơ-ho
A18: 17 | B18: Chăm
A19: 18 | B19: Sán Dìu
A20: 19 | B20: Hrê
A21: 20 | B21: Mnông
A22: 21 | B22: Ra-glai
... A57: 99 | B57: Người nước ngoài

Sheet Loại PA
A1: Mã Loại PA | B1: Tên loại PA
A2: 1 | B2: 1-Tăng người tham gia
A3: 2 | B3: 2-Tăng tiền lương
A4: 3 | B4: 3-Giảm người tham gia
A5: 4 | B5: 4-Giảm tiền lương

Sheet Phương án
A1: Mã PA | B1: Tên PA
A3: TM | B3: TM - Tăng mới
A4: GH | B4: GH - Giảm hẳn
A5: DT | B5: DT - Đóng tiếp | H5: =IF(ISBLANK(G5),"",INDEX('Phương án'!$A:$A,MATCH(G5,tenphuongan,0)))
A6: DL | B6: DL - Đóng lại
A7: DC | B7: DC - Điều chỉnh
A8: GC | B8: GC - Đến hạn nhưng không đóng
A9: GB | B9: GB - Chuyển sang đóng BHXH bắt buộc
A10: GD | B10: GD - Chuyển đi
A11: DB | B11: DB - Đóng bù

Sheet DM Mức hưởng BHYT
A1: Mã | B1: Diễn giải
A2: 1 | B2: Được quỹ BHYT thanh toán 100% chi phí khám bệnh, chữa bệnh (KCB) thuộc phạm vi chi trả BHYT và không áp dụng giới hạn tỷ lệ thanh toán một số thuốc, hoá chất, vật tư y tế và dịch vụ kỹ thuật theo quy định của Bộ trưởng Bộ Y tế về danh mục và tỷ lệ, điều kiện thanh toán dịch vụ kỹ thuật; chi phí vận chuyển người bệnh từ tuyến huyện lên tuyến trên trong trường hợp cấp cứu hoặc khi đang điều trị nội trú phải chuyển tuyến chuyên môn kỹ thuật, bao gồm các đối tượng hưởng có ký hiệu là: CC, TE.
A3: 2 | B3: Được quỹ BHYT thanh toán 100% chi phí KCB thuộc phạm vi chi trả BHYT (có giới hạn tỷ lệ thanh toán một số thuốc, hoá chất, vật tư y tế và dịch vụ kỹ thuật theo quy định của Bộ trưởng Bộ Y tế); chi phí vận chuyển người bệnh từ tuyến huyện lên tuyến trên trong trường hợp cấp cứu hoặc khi đang điều trị nội trú phải chuyển tuyến chuyên môn kỹ thuật, bao gồm các đối tượng hưởng có ký hiệu là: CK, CB, KC, HN, DT, DK, XD, BT, TS, AK
A4: 3 | B4: Được quỹ BHYT thanh toán 95% chi phí KCB thuộc phạm vi chi trả BHYT (có giới hạn tỷ lệ thanh toán một số thuốc, hoá chất, vật tư y tế và dịch vụ kỹ thuật theo quy định của Bộ trưởng Bộ Y tế); 100% chi phí KCB tại tuyến xã và chi phí cho một lần KCB thấp hơn 15% tháng lương cơ sở, bao gồm các đối tượng hưởng có ký hiệu là: HT, TC, CN, TG, DS
A5: 4 | B5: Được quỹ BHYT thanh toán 80% chi phí KCB thuộc phạm vi chi trả BHYT (có giới hạn tỷ lệ thanh toán một số thuốc, hoá chất, vật tư y tế và dịch vụ kỹ thuật theo quy định của Bộ trưởng Bộ Y tế); 100% chi phí KCB tại tuyến xã và chi phí cho một lần KCB thấp hơn 15% tháng lương cơ sở, bao gồm các đối tượng hưởng có ký hiệu là: DN, HX, CH, NN, TK, HC, XK, TB, NO, CT, XB, TN, CS, XN, MS, HD, TQ, TA, TY, HG, LS, PV, HS, SV, GB, GD
A6: 5 | B6: Được quỹ BHYT thanh toán 100% chi phí KCB, kể cả chi phí KCB ngoài phạm vi được hưởng BHYT; chi phí vận chuyển, bao gồm các đối tượng hưởng có ký hiệu là QN, CA, CY

Sheet Mối quan hệ
A1: Mã Mối quan hệ | B1: Mối quan hệ
A2: 00 | B2: Chủ hộ
A3: 01 | B3: Vợ
A4: 02 | B4: Chồng
A5: 03 | B5: Bố
A6: 04 | B6: Mẹ
A7: 05 | B7: Em
A8: 06 | B8: Anh
A9: 07 | B9: Chị
A10: 08 | B10: Con
A11: 09 | B11: Cháu
A12: 10 | B12: Ông
... A23: 21 | B23: Chắt
A24: 99 | B24: Khác

Sheet Tinhcu
A1: Mã | B1: Tỉnh/thành phố
A2: 01 | B2: 01 - Thành phố Hà Nội
A3: 02 | B3: 02 - Tỉnh Hà Giang
A4: 04 | B4: 04 - Tỉnh Cao Bằng
A5: 06 | B5: 06 - Tỉnh Bắc Kạn
A6: 08 | B6: 08 - Tỉnh Tuyên Quang
A7: 10 | B7: 10 - Tỉnh Lào Cai
A8: 11 | B8: 11 - Tỉnh Điện Biên
A9: 12 | B9: 12 - Tỉnh Lai Châu
A10: 14 | B10: 14 - Tỉnh Sơn La
A11: 15 | B11: 15 - Tỉnh Yên Bái
A12: 17 | B12: 17 - Tỉnh Hoà Bình
... A64: 96 | B64: 96 - Tỉnh Cà Mau
